mplus_output/bi-15-ELSA_W1.out
Mplus VERSION 8.1 (Mac)
MUTHEN & MUTHEN
05/27/2020  10:28 PM

INPUT INSTRUCTIONS

  DATA:
  FILE = "bi-15-ELSA_W1.dat";

  VARIABLE:
  NAMES = mplusid UDAT UDAY UMON UYER UIWR UDWR UANI ULET URE2 URE3 URE4 URE5 URE6
       UPM3 UPM4;
   MISSING=.;
   CATEGORICAL ARE all; idvariable = mplusid;
  ANALYSIS:
  estimator = wlsmv; coverage=0;
  MODEL:
  g by UDAT * ;
   g by UDAY * ;
   g by UMON * ;
   g by UYER * ;
   g by UIWR * ;
   g by UDWR * ;
   g by URE3 * ;
   g by URE5 * ;
   g by URE6 * ;
   g by UANI * ;
   g by ULET * ;
   g by URE2 * ;
   g by URE4 * ;
   g by UPM3 * ;
   g by UPM4 * ;
   s1 by UIWR @ 1 ;
   s1 by UDWR @ 1 ;
  s4 by UPM3 @ 1 ;
   s4 by UPM4 @ 1 ;
   g @ 1;
   s1 * ;
  s4 * ;
   g with s1 @ 0 ;
   g with s4 @ 0 ;
   s1 with s4 @ 0 ;
  OUTPUT:
  standardized; svalues;



*** WARNING
  Data set contains cases with missing on all variables.
  These cases were not included in the analysis.
  Number of cases with missing on all variables:  321
   1 WARNING(S) FOUND IN THE INPUT INSTRUCTIONS




SUMMARY OF ANALYSIS

Number of groups                                                 1
Number of observations                                       11778

Number of dependent variables                                   15
Number of independent variables                                  0
Number of continuous latent variables                            3

Observed dependent variables

  Binary and ordered categorical (ordinal)
   UDAT        UDAY        UMON        UYER        UIWR        UDWR
   UANI        ULET        URE2        URE3        URE4        URE5
   URE6        UPM3        UPM4

Continuous latent variables
   G           S1          S4

Variables with special functions

  ID variable           MPLUSID

Estimator                                                    WLSMV
Maximum number of iterations                                  1000
Convergence criterion                                    0.500D-04
Maximum number of steepest descent iterations                   20
Maximum number of iterations for H1                           2000
Convergence criterion for H1                             0.100D-03
Parameterization                                             DELTA
Link                                                        PROBIT

Input data file(s)
  bi-15-ELSA_W1.dat

Input data format  FREE


SUMMARY OF DATA

     Number of missing data patterns           165


COVARIANCE COVERAGE OF DATA

Minimum covariance coverage value   0.000


     PROPORTION OF DATA PRESENT


           Covariance Coverage
              UDAT          UDAY          UMON          UYER          UIWR
              ________      ________      ________      ________      ________
 UDAT           0.999
 UDAY           0.999         0.999
 UMON           0.999         0.999         0.999
 UYER           0.999         0.999         0.999         0.999
 UIWR           0.994         0.994         0.994         0.994         0.995
 UDWR           0.993         0.993         0.993         0.993         0.993
 UANI           0.994         0.994         0.994         0.994         0.994
 ULET           0.960         0.960         0.960         0.960         0.960
 URE2           0.970         0.970         0.970         0.970         0.969
 URE3           0.867         0.867         0.867         0.867         0.867
 URE4           0.702         0.702         0.702         0.702         0.702
 URE5           0.606         0.606         0.606         0.606         0.605
 URE6           0.619         0.619         0.619         0.619         0.619
 UPM3           0.869         0.869         0.869         0.869         0.868
 UPM4           0.787         0.787         0.787         0.787         0.787


           Covariance Coverage
              UDWR          UANI          ULET          URE2          URE3
              ________      ________      ________      ________      ________
 UDWR           0.993
 UANI           0.993         0.994
 ULET           0.959         0.960         0.960
 URE2           0.969         0.969         0.941         0.970
 URE3           0.867         0.867         0.845         0.861         0.867
 URE4           0.702         0.702         0.684         0.696         0.661
 URE5           0.605         0.605         0.591         0.603         0.585
 URE6           0.619         0.619         0.605         0.616         0.609
 UPM3           0.868         0.868         0.845         0.854         0.778
 UPM4           0.787         0.786         0.766         0.776         0.719


           Covariance Coverage
              URE4          URE5          URE6          UPM3          UPM4
              ________      ________      ________      ________      ________
 URE4           0.702
 URE5           0.506         0.606
 URE6           0.514         0.465         0.619
 UPM3           0.636         0.556         0.567         0.869
 UPM4           0.593         0.519         0.534         0.735         0.787


UNIVARIATE PROPORTIONS AND COUNTS FOR CATEGORICAL VARIABLES

    UDAT
      Category 1    0.192         2262.000
      Category 2    0.808         9508.000
    UDAY
      Category 1    0.021          242.000
      Category 2    0.979        11527.000
    UMON
      Category 1    0.026          301.000
      Category 2    0.974        11469.000
    UYER
      Category 1    0.028          324.000
      Category 2    0.972        11446.000
    UIWR
      Category 1    0.008           92.000
      Category 2    0.025          296.000
      Category 3    0.025          297.000
      Category 4    0.068          797.000
      Category 5    0.134         1573.000
      Category 6    0.454         5313.000
      Category 7    0.179         2097.000
      Category 8    0.080          942.000
      Category 9    0.023          264.000
      Category 10    0.004           44.000
    UDWR
      Category 1    0.093         1094.000
      Category 2    0.047          549.000
      Category 3    0.086         1009.000
      Category 4    0.136         1590.000
      Category 5    0.200         2346.000
      Category 6    0.332         3881.000
      Category 7    0.070          819.000
      Category 8    0.025          295.000
      Category 9    0.008           90.000
      Category 10    0.002           28.000
    UANI
      Category 1    0.009          106.000
      Category 2    0.005           59.000
      Category 3    0.033          384.000
      Category 4    0.122         1426.000
      Category 5    0.230         2689.000
      Category 6    0.261         3059.000
      Category 7    0.178         2089.000
      Category 8    0.100         1174.000
      Category 9    0.042          491.000
      Category 10    0.020          236.000
    ULET
      Category 1    0.017          189.000
      Category 2    0.047          529.000
      Category 3    0.102         1154.000
      Category 4    0.246         2781.000
      Category 5    0.237         2675.000
      Category 6    0.238         2695.000
      Category 7    0.052          588.000
      Category 8    0.034          379.000
      Category 9    0.012          137.000
      Category 10    0.016          183.000
    URE2
      Category 1    0.014          165.000
      Category 2    0.986        11257.000
    URE3
      Category 1    0.072          740.000
      Category 2    0.928         9477.000
    URE4
      Category 1    0.228         1886.000
      Category 2    0.772         6384.000
    URE5
      Category 1    0.189         1351.000
      Category 2    0.811         5782.000
    URE6
      Category 1    0.164         1195.000
      Category 2    0.598         4356.000
      Category 3    0.238         1738.000
    UPM3
      Category 1    0.037          381.000
      Category 2    0.310         3172.000
      Category 3    0.016          166.000
      Category 4    0.037          378.000
      Category 5    0.600         6135.000
    UPM4
      Category 1    0.274         2536.000
